Traceback (most recent call last):
  File "C:\Users\sayala\.conda\envs\RadWorkshop\Lib\site-packages\jupyter_cache\executors\utils.py", line 58, in single_nb_execution
    executenb(
  File "C:\Users\sayala\.conda\envs\RadWorkshop\Lib\site-packages\nbclient\client.py", line 1314, in execute
    return NotebookClient(nb=nb, resources=resources, km=km, **kwargs).execute()
           ^^^^^^^^^^^^^^^^^^^^^^^^^^^^^^^^^^^^^^^^^^^^^^^^^^^^^^^^^^^^^^^^^^^^^
  File "C:\Users\sayala\.conda\envs\RadWorkshop\Lib\site-packages\jupyter_core\utils\__init__.py", line 165, in wrapped
    return loop.run_until_complete(inner)
           ^^^^^^^^^^^^^^^^^^^^^^^^^^^^^^
  File "C:\Users\sayala\.conda\envs\RadWorkshop\Lib\asyncio\base_events.py", line 687, in run_until_complete
    return future.result()
           ^^^^^^^^^^^^^^^
  File "C:\Users\sayala\.conda\envs\RadWorkshop\Lib\site-packages\nbclient\client.py", line 709, in async_execute
    await self.async_execute_cell(
  File "C:\Users\sayala\.conda\envs\RadWorkshop\Lib\site-packages\nbclient\client.py", line 1062, in async_execute_cell
    await self._check_raise_for_error(cell, cell_index, exec_reply)
  File "C:\Users\sayala\.conda\envs\RadWorkshop\Lib\site-packages\nbclient\client.py", line 918, in _check_raise_for_error
    raise CellExecutionError.from_cell_and_msg(cell, exec_reply_content)
nbclient.exceptions.CellExecutionError: An error occurred while executing the following cell:
------------------
workflow2.generate_matrices()
------------------


[1;31m---------------------------------------------------------------------------[0m
[1;31mKeyError[0m                                  Traceback (most recent call last)
Cell [1;32mIn[12], line 1[0m
[1;32m----> 1[0m [43mworkflow2[49m[38;5;241;43m.[39;49m[43mgenerate_matrices[49m[43m([49m[43m)[49m

File [1;32m~\Documents\GitHub\tutorials\RadianceWorkshop\frads\frads\methods.py:796[0m, in [0;36mTwoPhaseMethod.generate_matrices[1;34m(self)[0m
[0;32m    794[0m [38;5;66;03m# First check if matrices files already exist[39;00m
[0;32m    795[0m [38;5;28;01mif[39;00m [38;5;28mself[39m[38;5;241m.[39mmfile[38;5;241m.[39mexists() [38;5;129;01mand[39;00m ([38;5;129;01mnot[39;00m [38;5;28mself[39m[38;5;241m.[39mconfig[38;5;241m.[39msettings[38;5;241m.[39moverwrite):
[1;32m--> 796[0m     [38;5;28;43mself[39;49m[38;5;241;43m.[39;49m[43mload_matrices[49m[43m([49m[43m)[49m
[0;32m    797[0m     [38;5;28;01mreturn[39;00m
[0;32m    798[0m [38;5;66;03m# Then check if overwrite is set to True[39;00m

File [1;32m~\Documents\GitHub\tutorials\RadianceWorkshop\frads\frads\methods.py:823[0m, in [0;36mTwoPhaseMethod.load_matrices[1;34m(self)[0m
[0;32m    821[0m     mtx[38;5;241m.[39marray [38;5;241m=[39m mdata[[38;5;124mf[39m[38;5;124m"[39m[38;5;132;01m{[39;00mview[38;5;132;01m}[39;00m[38;5;124m_sky_matrix[39m[38;5;124m"[39m]
[0;32m    822[0m [38;5;28;01mfor[39;00m sensor, mtx [38;5;129;01min[39;00m [38;5;28mself[39m[38;5;241m.[39msensor_sky_matrices[38;5;241m.[39mitems():
[1;32m--> 823[0m     mtx[38;5;241m.[39marray [38;5;241m=[39m [43mmdata[49m[43m[[49m[38;5;124;43mf[39;49m[38;5;124;43m"[39;49m[38;5;132;43;01m{[39;49;00m[43msensor[49m[38;5;132;43;01m}[39;49;00m[38;5;124;43m_sky_matrix[39;49m[38;5;124;43m"[39;49m[43m][49m

File [1;32m~\.conda\envs\RadWorkshop\Lib\site-packages\numpy\lib\_npyio_impl.py:265[0m, in [0;36mNpzFile.__getitem__[1;34m(self, key)[0m
[0;32m    263[0m         [38;5;28;01mreturn[39;00m [38;5;28mself[39m[38;5;241m.[39mzip[38;5;241m.[39mread(key)
[0;32m    264[0m [38;5;28;01melse[39;00m:
[1;32m--> 265[0m     [38;5;28;01mraise[39;00m [38;5;167;01mKeyError[39;00m([38;5;124mf[39m[38;5;124m"[39m[38;5;132;01m{[39;00mkey[38;5;132;01m}[39;00m[38;5;124m is not a file in the archive[39m[38;5;124m"[39m)

[1;31mKeyError[0m: 'view1_sky_matrix is not a file in the archive'

